Traceback (most recent call last):
  File "main.py", line 58, in <module>
    exp.run_experiment()
  File "main.py", line 53, in run_experiment
    self.plotter.plot()
  File "/home/lukas/work/experiments/plot.py", line 44, in plot
    plot.create_plot(self.path, self.results)
  File "/home/lukas/work/experiments/plot.py", line 22, in create_plot
    plt.plot(data[self.x], data[self.y_list[i]], self.format[i+1])
IndexError: list index out of range
